Workbook

Sheet Sheet6
A1: Census Tract | B1: tract | C1: Town | D1: Distressed Tract1 | E1: CLM $ Collected | F1: % of Total CLM $ Collected | G1: Incentive Disbursements | H1: % of Total Incentive Disbursements | I1: Column1 | J1: Equitable | K1: Residential CLM $ Collected | L1: % of Total Residential CLM $ Collected | M1: Residential Incentive Disbursements | N1: % of Total Residential Incentive Disbursements | O1: Equitable 2 | P1: C&I CLM $ Collected | Q1: % of Total C&I CLM $ Collected | R1: C&I Incentive Disbursements | S1: % of TotalC&I Incentive Disbursements | T1: Equitable 3 | U1: diversity index table.adjusted income (thousands of $) | V1: diversity index table.median census housing cost | W1: diversity index table.Combined affluence rank | X1: diversity index table.rural rank | Y1: diversity index table.racial diversity index | Z1: diversity index table.composit index | AA1: diversity index table.rounded composite
A2: 9001070200 | B2: 9001070200 | C2: BRIDGEPORT | D2: No | E2: 0 | F2: 0 | G2: 8670.73 | H2: 0.00051608453 | I2: YES | J2: N/A | K2: 0 | L2: 0 | M2: 2227.93 | N2: 0.00051608453 | O2: N/A | P2: 0 | Q2: 0 | R2: 6442.8 | S2: 0.00051608453 | T2: N/A | U2: 27.729 | V2: 1292 | W2: 5 | X2: 1 | Y2: 4 | Z2: 4.5 | AA2: 5
A3: 9001070200 | B3: 9001070200 | C3: Bridgeport | D3: Yes | E3: 67503.345 | F3: 0.0023196537 | G3: 0 | H3: 0 | I3: N/A | J3: NO | K3: 45704.852 | L3: 0.0023196537 | M3: 0 | N3: 0 | O3: NO | P3: 21798.492 | Q3: 0.0023196537 | R3: 0 | S3: 0 | T3: NO | U3: 27.729 | V3: 1292 | W3: 5 | X3: 1 | Y3: 4 | Z3: 4.5 | AA3: 5
A4: 9001070200 | B4: 9001070200 | C4: TRUMBULL | D4: No | E4: 0 | F4: 0 | G4: 749.66 | H4: 4.4619995e-05 | I4: YES | J4: N/A | K4: 0 | L4: 0 | M4: 749.66 | N4: 4.4619995e-05 | O4: N/A | P4: 0 | Q4: 0 | R4: 0 | S4: 4.4619995e-05 | T4: N/A | U4: 27.729 | V4: 1292 | W4: 5 | X4: 1 | Y4: 4 | Z4: 4.5 | AA4: 5
A5: 9001070300 | B5: 9001070300 | C5: BRIDGEPORT | D5: No | E5: 0 | F5: 0 | G5: 213519.3 | H5: 0.012708735 | I5: YES | J5: N/A | K5: 0 | L5: 0 | M5: 202635.3 | N5: 0.012708735 | O5: N/A | P5: 0 | Q5: 0 | R5: 10884 | S5: 0.012708735 | T5: N/A | U5: 5.532 | V5: 433 | W5: 5 | X5: 1 | Y5: 4 | Z5: 4.5 | AA5: 5
A6: 9001070300 | B6: 9001070300 | C6: Bridgeport | D6: Yes | E6: 52641.309 | F6: 0.0018089416 | G6: 0 | H6: 0 | I6: N/A | J6: NO | K6: 16956.724 | L6: 0.0018089416 | M6: 0 | N6: 0 | O6: NO | P6: 35684.585 | Q6: 0.0018089416 | R6: 0 | S6: 0 | T6: NO | U6: 5.532 | V6: 433 | W6: 5 | X6: 1 | Y6: 4 | Z6: 4.5 | AA6: 5
A7: 9001071100 | B7: 9001071100 | C7: Bridgeport | D7: No | E7: 66899.111 | F7: 0.0022988901 | G7: 29836.83 | H7: 0.0017758973 | I7: NO | J7: NO | K7: 51783.79 | L7: 0.0022988901 | M7: 21423.83 | N7: 0.0017758973 | O7: NO | P7: 15115.321 | Q7: 0.0022988901 | R7: 8413 | S7: 0.0017758973 | T7: NO | U7: 25.633 | V7: 1271 | W7: 5 | X7: 1 | Y7: 5 | Z7: 5 | AA7: 5
A8: 9001071200 | B8: 9001071200 | C8: BRIDGEPORT | D8: No | E8: 0 | F8: 0 | G8: 20104.86 | H8: 0.0011966475 | I8: YES | J8: N/A | K8: 0 | L8: 0 | M8: 4593.86 | N8: 0.0011966475 | O8: N/A | P8: 0 | Q8: 0 | R8: 15511 | S8: 0.0011966475 | T8: N/A | U8: 13.99 | V8: 1107 | W8: 5 | X8: 1 | Y8: 5 | Z8: 5 | AA8: 5
A9: 9001071200 | B9: 9001071200 | C9: Bridgeport | D9: Yes | E9: 65667.876 | F9: 0.0022565805 | G9: 0 | H9: 0 | I9: N/A | J9: NO | K9: 45169.658 | L9: 0.0022565805 | M9: 0 | N9: 0 | O9: NO | P9: 20498.218 | Q9: 0.0022565805 | R9: 0 | S9: 0 | T9: NO | U9: 13.99 | V9: 1107 | W9: 5 | X9: 1 | Y9: 5 | Z9: 5 | AA9: 5
A10: 9001071300 | B10: 9001071300 | C10: BRIDGEPORT | D10: No | E10: 0 | F10: 0 | G10: 2772.32 | H10: 0.00016500934 | I10: YES | J10: N/A | K10: 0 | L10: 0 | M10: 1572.32 | N10: 0.00016500934 | O10: N/A | P10: 0 | Q10: 0 | R10: 1200 | S10: 0.00016500934 | T10: N/A | U10: 17.511 | V10: 1078 | W10: 5 | X10: 1 | Y10: 5 | Z10: 5 | AA10: 5
A11: 9001071300 | B11: 9001071300 | C11: Bridgeport | D11: Yes | E11: 54252.862 | F11: 0.0018643203 | G11: 0 | H11: 0 | I11: N/A | J11: NO | K11: 34389.421 | L11: 0.0018643203 | M11: 0 | N11: 0 | O11: NO | P11: 19863.441 | Q11: 0.0018643203 | R11: 0 | S11: 0 | T11: NO | U11: 17.511 | V11: 1078 | W11: 5 | X11: 1 | Y11: 5 | Z11: 5 | AA11: 5
A12: 9001071400 | B12: 9001071400 | C12: Bridgeport | D12: No | E12: 68350.447 | F12: 0.0023487632 | G12: 10239.37 | H12: 0.00060945047 | I12: NO | J12: NO | K12: 38432.276 | L12: 0.0023487632 | M12: 3327.16 | N12: 0.00060945047 | O12: NO | P12: 29918.171 | Q12: 0.0023487632 | R12: 6912.21 | S12: 0.00060945047 | T12: NO | U12: 22.64 | V12: 1131 | W12: 5 | X12: 1 | Y12: 5 | Z12: 5 | AA12: 5
A13: 9001071900 | B13: 9001071900 | C13: ANSONIA | D13: No | E13: 0 | F13: 0 | G13: 230 | H13: 1.3689671e-05 | I13: YES | J13: N/A | K13: 0 | L13: 0 | M13: 230 | N13: 1.3689671e-05 | O13: N/A | P13: 0 | Q13: 0 | R13: 0 | S13: 1.3689671e-05 | T13: N/A | U13: 26.15 | V13: 1287 | W13: 5 | X13: 1 | Y13: 5 | Z13: 5 | AA13: 5
... A117: 9009361402 | B117: 9009361402 | C117: New Haven | D117: Yes | E117: 40495.789 | F117: 0.0013915786 | G117: 0 | H117: 0 | I117: N/A | J117: NO | K117: 4781.3609 | L117: 0.0013915786 | M117: 0 | N117: 0 | O117: NO | P117: 35714.428 | Q117: 0.0013915786 | R117: 0 | S117: 0 | T117: NO | U117: 35.178 | V117: 1510 | W117: 4 | X117: 1 | Y117: 5 | Z117: 4.5 | AA117: 5
E120: =SUM(Merge5[CLM $ Collected ]) -> 3329185.9
F124: =E120+Sheet8!D64 -> 5940952.7

Sheet small load equity calcs
A1: Census Tract | B1: tract | C1: Town | D1: Distressed Tract1 | E1: CLM $ Collected | F1: % of Total CLM $ Collected | G1: Incentive Disbursements | H1: % of Total Incentive Disbursements | I1: Column1 | J1: Equitable | K1: Residential CLM $ Collected | L1: % of Total Residential CLM $ Collected | M1: Residential Incentive Disbursements | N1: % of Total Residential Incentive Disbursements | O1: Equitable 2 | P1: C&I CLM $ Collected | Q1: % of Total C&I CLM $ Collected | R1: C&I Incentive Disbursements | S1: % of TotalC&I Incentive Disbursements | T1: Equitable 3 | U1: diversity index table.adjusted income (thousands of $) | V1: diversity index table.median census housing cost | W1: diversity index table.Combined affluence rank | X1: diversity index table.rural rank | Y1: diversity index table.racial diversity index | Z1: diversity index table.composit index | AA1: diversity index table.rounded composite
A2: 9001055100 | B2: 9001055100 | C2: Easton | D2: No | E2: 394.428 | F2: 1.3553941e-05 | G2: 0 | H2: 0 | I2: N/A | J2: NO | K2: 394.428 | L2: 1.3553941e-05 | M2: 0 | N2: 0 | O2: NO | P2: 0 | Q2: 1.3553941e-05 | R2: 0 | S2: 0 | T2: NO | U2: 118.302 | V2: 4000 | W2: 1 | X2: 1 | Y2: 4 | Z2: 2.5 | AA2: 3
A3: 9001055200 | B3: 9001055200 | C3: Easton | D3: No | E3: 887.5106 | F3: 3.0498004e-05 | G3: 0 | H3: 0 | I3: N/A | J3: NO | K3: 887.5106 | L3: 3.0498004e-05 | M3: 0 | N3: 0 | O3: NO | P3: 0 | Q3: 3.0498004e-05 | R3: 0 | S3: 0 | T3: NO | U3: 141.638 | V3: 3750 | W3: 1 | X3: 1 | Y3: 1 | Z3: 1 | AA3: 1 | AC3: Row Labels | AD3: Sum of CLM $ Collected | AE3: Sum of Incentive Disbursements | AF3: Sum of Residential CLM $ Collected | AG3: Sum of Residential Incentive Disbursements | AH3: Sum of C&I CLM $ Collected | AI3: Sum of C&I Incentive Disbursements | AJ3: Composite Index
A4: 9001060100 | B4: 9001060100 | C4: Bridgeport | D4: No | E4: 0.9029 | F4: 3.1026838e-08 | G4: 0 | H4: 0 | I4: N/A | J4: N/A | K4: 0 | L4: 3.1026838e-08 | M4: 0 | N4: 0 | O4: N/A | P4: 0.9029 | Q4: 3.1026838e-08 | R4: 0 | S4: 0 | T4: N/A | U4: 85.387 | V4: 2313 | W4: 1 | X4: 1 | Y4: 2 | Z4: 1.5 | AA4: 2 | AC4: 1 | AD4: 1535395.4 | AE4: 489966.54 | AF4: 1233439.3 | AG4: 355917.5 | AH4: 301956.11 | AI4: 134049.04
A5: 9001060100 | B5: 9001060100 | C5: Fairfield | D5: No | E5: 71392.777 | F5: 0.0024533084 | G5: 20104.8 | H5: 0.0011966439 | I5: NO | J5: NO | K5: 58128.328 | L5: 0.0024533084 | M5: 19857.8 | N5: 0.0011966439 | O5: NO | P5: 13264.449 | Q5: 0.0024533084 | R5: 247 | S5: 0.0011966439 | T5: NO | U5: 85.387 | V5: 2313 | W5: 1 | X5: 1 | Y5: 2 | Z5: 1.5 | AA5: 2 | AC5: 2 | AD5: 2438778.6 | AE5: 840590.69 | AF5: 1849524.4 | AG5: 641461.43 | AH5: 589254.16 | AI5: 199129.26 | AK5: Row Labels | AL5: Sum of CLM $ Collected | AM5: Sum of Incentive Disbursements | AN5: Sum of Residential CLM $ Collected | AO5: Sum of Residential Incentive Disbursements | AP5: Sum of C&I CLM $ Collected | AQ5: Sum of C&I Incentive Disbursements
A6: 9001060100 | B6: 9001060100 | C6: Trumbull | D6: No | E6: 106.0054 | F6: 3.6427206e-06 | G6: 0 | H6: 0 | I6: N/A | J6: N/A | K6: 0 | L6: 3.6427206e-06 | M6: 0 | N6: 0 | O6: N/A | P6: 106.0054 | Q6: 3.6427206e-06 | R6: 0 | S6: 0 | T6: N/A | U6: 85.387 | V6: 2313 | W6: 1 | X6: 1 | Y6: 2 | Z6: 1.5 | AA6: 2 | AC6: 3 | AD6: 4435476.1 | AE6: 1795986.2 | AF6: 3153797.1 | AG6: 1288734.7 | AH6: 1281679 | AI6: 507251.52 | AK6: 1 | AL6: 875724.39 | AM6: 163490.93 | AN6: 721825.63 | AO6: 144167.93 | AP6: 153898.77 | AQ6: 19323
A7: 9001060200 | B7: 9001060200 | C7: Fairfield | D7: No | E7: 96972.012 | F7: 0.0033323014 | G7: 31534.58 | H7: 0.001876948 | I7: NO | J7: NO | K7: 78630.955 | L7: 0.0033323014 | M7: 29656.58 | N7: 0.001876948 | O7: NO | P7: 18341.057 | Q7: 0.0033323014 | R7: 1878 | S7: 0.001876948 | T7: NO | U7: 75.665 | V7: 2452 | W7: 1 | X7: 1 | Y7: 3 | Z7: 2 | AA7: 2 | AC7: 4 | AD7: 4048969.2 | AE7: 2234279.7 | AF7: 2680511.7 | AG7: 1554367.5 | AH7: 1368457.5 | AI7: 679912.24 | AK7: 2 | AL7: 2632944.6 | AM7: 1054449.1 | AN7: 2127184.9 | AO7: 766959.85 | AP7: 505759.68 | AQ7: 287489.29
A8: 9001060300 | B8: 9001060300 | C8: Fairfield | D8: No | E8: 100651.49 | F8: 0.0034587413 | G8: 19540.71 | H8: 0.0011630691 | I8: NO | J8: NO | K8: 92872.917 | L8: 0.0034587413 | M8: 19540.71 | N8: 0.0011630691 | O8: NO | P8: 7778.5729 | Q8: 0.0034587413 | R8: 0 | S8: 0.0011630691 | T8: NO | U8: 114.261 | V8: 3341 | W8: 1 | X8: 1 | Y8: 2 | Z8: 1.5 | AA8: 2 | AC8: 5 | AD8: 5080239.7 | AE8: 2194563.5 | AF8: 3212520.4 | AG8: 1176273.2 | AH8: 1867719.3 | AI8: 1018290.3 | AK8: 3 | AL8: 4733189.1 | AM8: 1902360.5 | AN8: 3270324 | AO8: 1307531.1 | AP8: 1462865.1 | AQ8: 594829.38
A9: 9001060400 | B9: 9001060400 | C9: Fairfield | D9: No | E9: 167953.61 | F9: 0.0057714803 | G9: 16361.63 | H9: 0.00097384928 | I9: NO | J9: NO | K9: 158569.58 | L9: 0.0057714803 | M9: 16361.63 | N9: 0.00097384928 | O9: NO | P9: 9384.0322 | Q9: 0.0057714803 | R9: 0 | S9: 0.00097384928 | T9: NO | U9: 146.927 | V9: 3810 | W9: 1 | X9: 1 | Y9: 1 | Z9: 1 | AA9: 1 | AC9: Grand Total | AD9: 17538859 | AE9: 7555386.7 | AF9: 12129793 | AG9: 5016754.3 | AH9: 5409066.1 | AI9: 2538632.3 | AK9: 4 | AL9: 4235912 | AM9: 2387206.9 | AN9: 2789481.1 | AO9: 1387531.3 | AP9: 1446431 | AQ9: 999675.57
A10: 9001060500 | B10: 9001060500 | C10: Fairfield | D10: No | E10: 77707.49 | F10: 0.0026703043 | G10: 7351.8 | H10: 0.00043758141 | I10: NO | J10: NO | K10: 71345.134 | L10: 0.0026703043 | M10: 7351.8 | N10: 0.00043758141 | O10: NO | P10: 6362.3551 | Q10: 0.0026703043 | R10: 0 | S10: 0.00043758141 | T10: NO | U10: 121.599 | V10: 3418 | W10: 1 | X10: 1 | Y10: 1 | Z10: 1 | AA10: 1 | AK10: 5 | AL10: 5061088.8 | AM10: 2047879.2 | AN10: 3220977.3 | AO10: 1410564.1 | AP10: 1840111.5 | AQ10: 637315.1
A11: 9001060600 | B11: 9001060600 | C11: Fairfield | D11: No | E11: 122971.58 | F11: 0.0042257384 | G11: 95807 | H11: 0.0057024623 | I11: YES | J11: YES | K11: 73188.417 | L11: 0.0042257384 | M11: 6296 | N11: 0.0057024623 | O11: YES | P11: 49783.158 | Q11: 0.0042257384 | R11: 89511 | S11: 0.0057024623 | T11: YES | U11: 116.734 | V11: 2525 | W11: 1 | X11: 1 | Y11: 2 | Z11: 1.5 | AA11: 2 | AK11: Grand Total | AL11: 17538859 | AM11: 7555386.7 | AN11: 12129793 | AO11: 5016754.3 | AP11: 5409066.1 | AQ11: 2538632.3
A12: 9001060700 | B12: 9001060700 | C12: Fairfield | D12: No | E12: 117727.44 | F12: 0.0040455315 | G12: 8336.04 | H12: 0.00049616368 | I12: NO | J12: NO | K12: 98856.621 | L12: 0.0040455315 | M12: 8336.04 | N12: 0.00049616368 | O12: NO | P12: 18870.823 | Q12: 0.0040455315 | R12: 0 | S12: 0.00049616368 | T12: NO | U12: 104.15 | V12: 2864 | W12: 1 | X12: 1 | Y12: 2 | Z12: 1.5 | AA12: 2
A13: 9001060800 | B13: 9001060800 | C13: Fairfield | D13: No | E13: 41183.172 | F13: 0.0014151995 | G13: 4387.52 | H13: 0.00026114655 | I13: NO | J13: NO | K13: 39085.891 | L13: 0.0014151995 | M13: 4387.52 | N13: 0.00026114655 | O13: NO | P13: 2097.2804 | Q13: 0.0014151995 | R13: 0 | S13: 0.00026114655 | T13: NO | U13: 103.645 | V13: 3043 | W13: 1 | X13: 1 | Y13: 2 | Z13: 1.5 | AA13: 2 | AK13: Row Labels | AL13: Collections % | AM13: Collections Disbursement | AN13: RES collections | AO13: RES disbursements | AP13: C&I Collection | AQ13: C&I disburse
A14: 9001060900 | B14: 9001060900 | C14: Fairfield | D14: No | E14: 49269.364 | F14: 0.0016930697 | G14: 30036.3 | H14: 0.0017877699 | I14: YES | J14: YES | K14: 48889.4 | L14: 0.0016930697 | M14: 30036.3 | N14: 0.0017877699 | O14: YES | P14: 379.9641 | Q14: 0.0016930697 | R14: 0 | S14: 0.0017877699 | T14: YES | U14: 82.66 | V14: 2698 | W14: 1 | X14: 1 | Y14: 1 | Z14: 1 | AA14: 1 | AK14: 1 | AL14: =AL6/AL$11 -> 0.049930523 | AM14: =AM6/AM$11 -> 0.021638989 | AN14: =AN6/AN$11 -> 0.059508487 | AO14: =AO6/AO$11 -> 0.028737291 | AP14: =AP6/AP$11 -> 0.028452004 | AQ14: =AQ6/AQ$11 -> 0.0076115788
A15: 9001061000 | B15: 9001061000 | C15: Fairfield | D15: No | E15: 141435.5 | F15: 0.0048602243 | G15: 84443.99 | H15: 0.0050261324 | I15: YES | J15: YES | K15: 73580.641 | L15: 0.0048602243 | M15: 75486.32 | N15: 0.0050261324 | O15: YES | P15: 67854.863 | Q15: 0.0048602243 | R15: 8957.67 | S15: 0.0050261324 | T15: YES | U15: 49.471 | V15: 1741 | W15: 3 | X15: 1 | Y15: 3 | Z15: 3 | AA15: 3 | AK15: 2 | AL15: =AL7/AL$11 -> 0.15012063 | AM15: =AM7/AM$11 -> 0.13956256 | AN15: =AN7/AN$11 -> 0.17536861 | AO15: =AO7/AO$11 -> 0.15287969 | AP15: =AP7/AP$11 -> 0.093502219 | AQ15: =AQ7/AQ$11 -> 0.11324574
A16: 9001061100 | B16: 9001061100 | C16: Fairfield | D16: No | E16: 72876.103 | F16: 0.0025042807 | G16: 4473.07 | H16: 0.00026623851 | I16: NO | J16: NO | K16: 67549.059 | L16: 0.0025042807 | M16: 4173.07 | N16: 0.00026623851 | O16: NO | P16: 5327.0441 | Q16: 0.0025042807 | R16: 300 | S16: 0.00026623851 | T16: NO | U16: 94.519 | V16: 2692 | W16: 1 | X16: 1 | Y16: 1 | Z16: 1 | AA16: 1 | AK16: 3 | AL16: =AL8/AL$11 -> 0.2698687 | AM16: =AM8/AM$11 -> 0.25178863 | AN16: =AN8/AN$11 -> 0.26961087 | AO16: =AO8/AO$11 -> 0.26063287 | AP16: =AP8/AP$11 -> 0.2704469 | AQ16: =AQ8/AQ$11 -> 0.23431096
A17: 9001061200 | B17: 9001061200 | C17: Fairfield | D17: No | E17: 37465.91 | F17: 0.0012874612 | G17: 19703.03 | H17: 0.0011727304 | I17: YES | J17: NO | K17: 35405.152 | L17: 0.0012874612 | M17: 19213.03 | N17: 0.0011727304 | O17: NO | P17: 2060.7587 | Q17: 0.0012874612 | R17: 490 | S17: 0.0011727304 | T17: NO | U17: 48.123 | V17: 1853 | W17: 3 | X17: 1 | Y17: 5 | Z17: 4 | AA17: 4 | AK17: 4 | AL17: =AL9/AL$11 -> 0.24151583 | AM17: =AM9/AM$11 -> 0.31596092 | AN17: =AN9/AN$11 -> 0.22996939 | AO17: =AO9/AO$11 -> 0.27657949 | AP17: =AP9/AP$11 -> 0.26740863 | AQ17: =AQ9/AQ$11 -> 0.39378509
A18: 9001061300 | B18: 9001061300 | C18: Fairfield | D18: No | E18: 75361.948 | F18: 0.0025897032 | G18: 35125.23 | H18: 0.0020906646 | I18: NO | J18: NO | K18: 51750.384 | L18: 0.0025897032 | M18: 7224.19 | N18: 0.0020906646 | O18: NO | P18: 23611.565 | Q18: 0.0025897032 | R18: 27901.04 | S18: 0.0020906646 | T18: NO | U18: 54.923 | V18: 1857 | W18: 3 | X18: 1 | Y18: 4 | Z18: 3.5 | AA18: 4 | AK18: 5 | AL18: =AL10/AL$11 -> 0.28856431 | AM18: =AM10/AM$11 -> 0.2710489 | AN18: =AN10/AN$11 -> 0.26554264 | AO18: =AO10/AO$11 -> 0.28117066 | AP18: =AP10/AP$11 -> 0.34019025 | AQ18: =AQ10/AQ$11 -> 0.25104663
A19: 9001061400 | B19: 9001061400 | C19: Fairfield | D19: No | E19: 118695.18 | F19: 0.0040787861 | G19: 8852.19 | H19: 0.00052688509 | I19: NO | J19: NO | K19: 47281.252 | L19: 0.0040787861 | M19: 5299.19 | N19: 0.00052688509 | O19: NO | P19: 71413.923 | Q19: 0.0040787861 | R19: 3553 | S19: 0.00052688509 | T19: NO | U19: 56.725 | V19: 1873 | W19: 3 | X19: 1 | Y19: 5 | Z19: 4 | AA19: 4
A20: 9001061500 | B20: 9001061500 | C20: Bridgeport | D20: No | E20: 539.357 | F20: 1.8534215e-05 | G20: 0 | H20: 0 | I20: N/A | J20: NO | K20: 0 | L20: 1.8534215e-05 | M20: 0 | N20: 0 | O20: NO | P20: 539.357 | Q20: 1.8534215e-05 | R20: 0 | S20: 0 | T20: NO | U20: 89.569 | V20: 2670 | W20: 1 | X20: 1 | Y20: 4 | Z20: 2.5 | AA20: 3 | AJ20: Affluence index
A21: 9001061500 | B21: 9001061500 | C21: Fairfield | D21: No | E21: 188421.01 | F21: 0.0064748126 | G21: 34700.67 | H21: 0.0020653946 | I21: NO | J21: NO | K21: 104123.37 | L21: 0.0064748126 | M21: 13917.12 | N21: 0.0020653946 | O21: NO | P21: 84297.644 | Q21: 0.0064748126 | R21: 20783.55 | S21: 0.0020653946 | T21: NO | U21: 89.569 | V21: 2670 | W21: 1 | X21: 1 | Y21: 4 | Z21: 2.5 | AA21: 3 | AK21: Row Labels | AL21: Sum of CLM $ Collected | AM21: Sum of Incentive Disbursements | AN21: Sum of Residential CLM $ Collected | AO21: Sum of Residential Incentive Disbursements | AP21: Sum of C&I CLM $ Collected | AQ21: Sum of C&I Incentive Disbursements
A22: 9001061600 | B22: 9001061600 | C22: Fairfield | D22: No | E22: 182195.89 | F22: 0.0062608955 | G22: 24755.48 | H22: 0.0014734538 | I22: NO | J22: NO | K22: 114122.91 | L22: 0.0062608955 | M22: 10431.48 | N22: 0.0014734538 | O22: NO | P22: 68072.98 | Q22: 0.0062608955 | R22: 14324 | S22: 0.0014734538 | T22: NO | U22: 80.624 | V22: 2370 | W22: 1 | X22: 1 | Y22: 1 | Z22: 1 | AA22: 1 | AK22: 1 | AL22: 2809461.1 | AM22: 878020.93 | AN22: 2230487.9 | AO22: 652857.03 | AP22: 578973.19 | AQ22: 225163.9
A23: 9001070100 | B23: 9001070100 | C23: BRIDGEPORT | D23: No | E23: 0 | F23: 0 | G23: 11586.15 | H23: 0.00068961123 | I23: YES | J23: N/A | K23: 0 | L23: 0 | M23: 11088.15 | N23: 0.00068961123 | O23: N/A | P23: 0 | Q23: 0 | R23: 498 | S23: 0.00068961123 | T23: N/A | U23: 59.891 | V23: 1489 | W23: 3 | X23: 1 | Y23: 4 | Z23: 3.5 | AA23: 4 | AK23: 2 | AL23: 3647227 | AM23: 1769873.3 | AN23: 2501741.3 | AO23: 901132.89 | AP23: 1145485.7 | AQ23: 868740.37
A24: 9001070100 | B24: 9001070100 | C24: Bridgeport | D24: Yes | E24: 118414.09 | F24: 0.0040691272 | G24: 0 | H24: 0 | I24: N/A | J24: NO | K24: 87876.711 | L24: 0.0040691272 | M24: 0 | N24: 0 | O24: NO | P24: 30537.383 | Q24: 0.0040691272 | R24: 0 | S24: 0 | T24: NO | U24: 59.891 | V24: 1489 | W24: 3 | X24: 1 | Y24: 4 | Z24: 3.5 | AA24: 4 | AK24: 3 | AL24: 3700388.6 | AM24: 1973902.6 | AN24: 2519773.1 | AO24: 1416615.2 | AP24: 1180615.5 | AQ24: 557287.41
A25: 9001070200 | B25: 9001070200 | C25: BRIDGEPORT | D25: No | E25: 0 | F25: 0 | G25: 8670.73 | H25: 0.00051608453 | I25: YES | J25: N/A | K25: 0 | L25: 0 | M25: 2227.93 | N25: 0.00051608453 | O25: N/A | P25: 0 | Q25: 0 | R25: 6442.8 | S25: 0.00051608453 | T25: N/A | U25: 27.729 | V25: 1292 | W25: 5 | X25: 1 | Y25: 4 | Z25: 4.5 | AA25: 5 | AK25: 4 | AL25: 3405799.7 | AM25: 1248759.9 | AN25: 2420231.1 | AO25: 904056.85 | AP25: 985568.57 | AQ25: 344703.07
A26: 9001070200 | B26: 9001070200 | C26: Bridgeport | D26: Yes | E26: 67503.345 | F26: 0.0023196537 | G26: 0 | H26: 0 | I26: N/A | J26: NO | K26: 45704.852 | L26: 0.0023196537 | M26: 0 | N26: 0 | O26: NO | P26: 21798.492 | Q26: 0.0023196537 | R26: 0 | S26: 0 | T26: NO | U26: 27.729 | V26: 1292 | W26: 5 | X26: 1 | Y26: 4 | Z26: 4.5 | AA26: 5 | AK26: 5 | AL26: 3975982.6 | AM26: 1684830 | AN26: 2457559.5 | AO26: 1142092.4 | AP26: 1518423 | AQ26: 542737.59
A27: 9001070200 | B27: 9001070200 | C27: TRUMBULL | D27: No | E27: 0 | F27: 0 | G27: 749.66 | H27: 4.4619995e-05 | I27: YES | J27: N/A | K27: 0 | L27: 0 | M27: 749.66 | N27: 4.4619995e-05 | O27: N/A | P27: 0 | Q27: 0 | R27: 0 | S27: 4.4619995e-05 | T27: N/A | U27: 27.729 | V27: 1292 | W27: 5 | X27: 1 | Y27: 4 | Z27: 4.5 | AA27: 5 | AK27: Grand Total | AL27: 17538859 | AM27: 7555386.7 | AN27: 12129793 | AO27: 5016754.3 | AP27: 5409066.1 | AQ27: 2538632.3
A28: 9001070300 | B28: 9001070300 | C28: BRIDGEPORT | D28: No | E28: 0 | F28: 0 | G28: 213519.3 | H28: 0.012708735 | I28: YES | J28: N/A | K28: 0 | L28: 0 | M28: 202635.3 | N28: 0.012708735 | O28: N/A | P28: 0 | Q28: 0 | R28: 10884 | S28: 0.012708735 | T28: N/A | U28: 5.532 | V28: 433 | W28: 5 | X28: 1 | Y28: 4 | Z28: 4.5 | AA28: 5
A29: 9001070300 | B29: 9001070300 | C29: Bridgeport | D29: Yes | E29: 52641.309 | F29: 0.0018089416 | G29: 0 | H29: 0 | I29: N/A | J29: NO | K29: 16956.724 | L29: 0.0018089416 | M29: 0 | N29: 0 | O29: NO | P29: 35684.585 | Q29: 0.0018089416 | R29: 0 | S29: 0 | T29: NO | U29: 5.532 | V29: 433 | W29: 5 | X29: 1 | Y29: 4 | Z29: 4.5 | AA29: 5 | AK29: Row Labels | AL29: Collections % | AM29: Collections Disbursement | AN29: RES collections | AO29: RES disbursements | AP29: C&I Collection | AQ29: C&I disburse
A30: 9001070400 | B30: 9001070400 | C30: BRIDGEPORT | D30: No | E30: 0 | F30: 0 | G30: 2503.53 | H30: 0.00014901088 | I30: YES | J30: N/A | K30: 0 | L30: 0 | M30: 1029.53 | N30: 0.00014901088 | O30: N/A | P30: 0 | Q30: 0 | R30: 1474 | S30: 0.00014901088 | T30: N/A | U30: 25.893 | V30: 912 | W30: 5 | X30: 1 | Y30: 5 | Z30: 5 | AA30: 5 | AK30: 1 | AL30: =AL22/AL$27 -> 0.16018494 | AM30: =AM22/AM$27 -> 0.11621125 | AN30: =AN22/AN$27 -> 0.18388508 | AO30: =AO22/AO$27 -> 0.13013534 | AP30: =AP22/AP$27 -> 0.10703755 | AQ30: =AQ22/AQ$27 -> 0.088694962
A31: 9001070400 | B31: 9001070400 | C31: Bridgeport | D31: Yes | E31: 23919.493 | F31: 0.0008219584 | G31: 0 | H31: 0 | I31: N/A | J31: NO | K31: 17866.172 | L31: 0.0008219584 | M31: 0 | N31: 0 | O31: NO | P31: 6053.3215 | Q31: 0.0008219584 | R31: 0 | S31: 0 | T31: NO | U31: 25.893 | V31: 912 | W31: 5 | X31: 1 | Y31: 5 | Z31: 5 | AA31: 5 | AK31: 2 | AL31: =AL23/AL$27 -> 0.20795121 | AM31: =AM23/AM$27 -> 0.23425317 | AN31: =AN23/AN$27 -> 0.20624765 | AO31: =AO23/AO$27 -> 0.17962468 | AP31: =AP23/AP$27 -> 0.21177145 | AQ31: =AQ23/AQ$27 -> 0.34220803
A32: 9001070400 | B32: 9001070400 | C32: Stratford | D32: Yes | E32: 50.8641 | F32: 1.7478704e-06 | G32: 0 | H32: 0 | I32: N/A | J32: N/A | K32: 50.8641 | L32: 1.7478704e-06 | M32: 0 | N32: 0 | O32: N/A | P32: 0 | Q32: 1.7478704e-06 | R32: 0 | S32: 0 | T32: N/A | U32: 25.893 | V32: 912 | W32: 5 | X32: 1 | Y32: 5 | Z32: 5 | AA32: 5 | AK32: 3 | AL32: =AL24/AL$27 -> 0.21098229 | AM32: =AM24/AM$27 -> 0.26125765 | AN32: =AN24/AN$27 -> 0.20773422 | AO32: =AO24/AO$27 -> 0.28237683 | AP32: =AP24/AP$27 -> 0.21826606 | AQ32: =AQ24/AQ$27 -> 0.21952269
A33: 9001070500 | B33: 9001070500 | C33: BRIDGEPORT | D33: No | E33: 0 | F33: 0 | G33: 16596.99 | H33: 0.00098785798 | I33: YES | J33: N/A | K33: 0 | L33: 0 | M33: 359.75 | N33: 0.00098785798 | O33: N/A | P33: 0 | Q33: 0 | R33: 16237.24 | S33: 0.00098785798 | T33: N/A | U33: 15.334 | V33: 1275 | W33: 5 | X33: 1 | Y33: 5 | Z33: 5 | AA33: 5 | AK33: 4 | AL33: =AL25/AL$27 -> 0.19418593 | AM33: =AM25/AM$27 -> 0.16528074 | AN33: =AN25/AN$27 -> 0.19952782 | AO33: =AO25/AO$27 -> 0.18020752 | AP33: =AP25/AP$27 -> 0.18220679 | AQ33: =AQ25/AQ$27 -> 0.13578298
A34: 9001070500 | B34: 9001070500 | C34: Bridgeport | D34: Yes | E34: 29086.941 | F34: 0.00099953018 | G34: 0 | H34: 0 | I34: N/A | J34: NO | K34: 23101.569 | L34: 0.00099953018 | M34: 0 | N34: 0 | O34: NO | P34: 5985.372 | Q34: 0.00099953018 | R34: 0 | S34: 0 | T34: NO | U34: 15.334 | V34: 1275 | W34: 5 | X34: 1 | Y34: 5 | Z34: 5 | AA34: 5 | AK34: 5 | AL34: =AL26/AL$27 -> 0.22669562 | AM34: =AM26/AM$27 -> 0.22299719 | AN34: =AN26/AN$27 -> 0.20260523 | AO34: =AO26/AO$27 -> 0.22765563 | AP34: =AP26/AP$27 -> 0.28071815 | AQ34: =AQ26/AQ$27 -> 0.21379133
A35: 9001070600 | B35: 9001070600 | C35: BRIDGEPORT | D35: No | E35: 0 | F35: 0 | G35: 110631.34 | H35: 0.0065848116 | I35: YES | J35: N/A | K35: 0 | L35: 0 | M35: 96774.69 | N35: 0.0065848116 | O35: N/A | P35: 0 | Q35: 0 | R35: 13856.65 | S35: 0.0065848116 | T35: N/A | U35: 18.833 | V35: 974 | W35: 5 | X35: 1 | Y35: 4 | Z35: 4.5 | AA35: 5
A36: 9001070600 | B36: 9001070600 | C36: Bridgeport | D36: Yes | E36: 144313.23 | F36: 0.0049591131 | G36: 0 | H36: 0 | I36: N/A | J36: NO | K36: 35967.757 | L36: 0.0049591131 | M36: 0 | N36: 0 | O36: NO | P36: 108345.47 | Q36: 0.0049591131 | R36: 0 | S36: 0 | T36: NO | U36: 18.833 | V36: 974 | W36: 5 | X36: 1 | Y36: 4 | Z36: 4.5 | AA36: 5 | AJ36: Racial Diversity
A37: 9001070900 | B37: 9001070900 | C37: BRIDGEPORT | D37: No | E37: 0 | F37: 0 | G37: 30327.01 | H37: 0.001805073 | I37: YES | J37: N/A | K37: 0 | L37: 0 | M37: 4170.01 | N37: 0.001805073 | O37: N/A | P37: 0 | Q37: 0 | R37: 26157 | S37: 0.001805073 | T37: N/A | U37: 20.158 | V37: 1228 | W37: 5 | X37: 1 | Y37: 5 | Z37: 5 | AA37: 5 | AK37: Row Labels | AL37: Sum of CLM $ Collected | AM37: Sum of Incentive Disbursements | AN37: Sum of Residential CLM $ Collected | AO37: Sum of Residential Incentive Disbursements | AP37: Sum of C&I CLM $ Collected | AQ37: Sum of C&I Incentive Disbursements
A38: 9001070900 | B38: 9001070900 | C38: Bridgeport | D38: Yes | E38: 40068.742 | F38: 0.0013769037 | G38: 0 | H38: 0 | I38: N/A | J38: NO | K38: 29174.959 | L38: 0.0013769037 | M38: 0 | N38: 0 | O38: NO | P38: 10893.783 | Q38: 0.0013769037 | R38: 0 | S38: 0 | T38: NO | U38: 20.158 | V38: 1228 | W38: 5 | X38: 1 | Y38: 5 | Z38: 5 | AA38: 5 | AK38: 1 | AL38: 1535395.4 | AM38: 489966.54 | AN38: 1233439.3 | AO38: 355917.5 | AP38: 301956.11 | AQ38: 134049.04
A39: 9001071000 | B39: 9001071000 | C39: BRIDGEPORT | D39: No | E39: 0 | F39: 0 | G39: 17169.5 | H39: 0.0010219339 | I39: YES | J39: N/A | K39: 0 | L39: 0 | M39: 14379.5 | N39: 0.0010219339 | O39: N/A | P39: 0 | Q39: 0 | R39: 2790 | S39: 0.0010219339 | T39: N/A | U39: 27.215 | V39: 1323 | W39: 5 | X39: 1 | Y39: 5 | Z39: 5 | AA39: 5 | AK39: 2 | AL39: 2438778.6 | AM39: 840590.69 | AN39: 1849524.4 | AO39: 641461.43 | AP39: 589254.16 | AQ39: 199129.26
A40: 9001071000 | B40: 9001071000 | C40: Bridgeport | D40: Yes | E40: 63545.393 | F40: 0.0021836445 | G40: 0 | H40: 0 | I40: N/A | J40: NO | K40: 37249.349 | L40: 0.0021836445 | M40: 0 | N40: 0 | O40: NO | P40: 26296.044 | Q40: 0.0021836445 | R40: 0 | S40: 0 | T40: NO | U40: 27.215 | V40: 1323 | W40: 5 | X40: 1 | Y40: 5 | Z40: 5 | AA40: 5 | AK40: 3 | AL40: 4435476.1 | AM40: 1795986.2 | AN40: 3153797.1 | AO40: 1288734.7 | AP40: 1281679 | AQ40: 507251.52
...

Sheet Sheet4
A1: Row Labels | B1: Sum of Residential CLM $ Collected | C1: Sum of Residential Incentive Disbursements
A2: 9001070300 | B2: 16956.724 | C2: 202635.3
A3: 9001070400 | B3: 17917.036 | C3: 1029.53 | K3: Row Labels | L3: Sum of Residential CLM $ Collected | M3: Sum of Residential Incentive Disbursements | N3: HESReportTable.Distressed Tract1 | O3: HESReportTable.CLM $ Collected | P3: HESReportTable.Incentive Disbursements | Q3: HESReportTable.HES Total Units | R3: HESReportTable.HES Single Family | S3: HESReportTable.HES 2-4 Units | T3: HESReportTable.HES >4 Units | U3: HESReportTable.Incentives | V3: HESReportTable.HESIE Total Units | W3: HESReportTable.HESIE Single Family | X3: HESReportTable.HESIE 2-4 Units2 | Y3: HESReportTable.HESIE >4 Units | Z3: HESReportTable.HESIE Incentives
A4: 9001070500 | B4: 23101.569 | C4: 359.75 | K4: 9001070300 | L4: 16956.724 | M4: 202635.3 | N4: No | O4: 0 | P4: 202635.3 | Q4: 0 | U4: 0 | V4: 2 | W4: 0 | X4: 1 | Y4: 1 | Z4: 202635.3
A5: 9001070900 | B5: 29174.959 | C5: 4170.01 | K5: 9001070300 | L5: 16956.724 | M5: 202635.3 | N5: Yes | O5: 16956.724 | P5: 0 | Q5: 0 | U5: 0 | V5: 0 | Z5: 0
A6: 9001071000 | B6: 37249.349 | C6: 14379.5 | K6: 9001070400 | L6: 17917.036 | M6: 1029.53 | N6: No | O6: 0 | P6: 1029.53 | Q6: 3 | R6: 3 | S6: 0 | T6: 0 | U6: 380.24 | V6: 6 | W6: 2 | X6: 4 | Y6: 0 | Z6: 649.29 | AB6: Row Labels | AC6: Sum of Sum of Residential CLM $ Collected | AD6: Sum of Sum of Residential Incentive Disbursements | AE6: Sum of HESReportTable.CLM $ Collected | AF6: Sum of HESReportTable.Incentive Disbursements | AG6: Sum of HESReportTable.Incentives | AH6: Sum of HESReportTable.HESIE Incentives | AI6: Sum of HESReportTable.HES Total Units | AJ6: Sum of HESReportTable.HESIE Total Units
A7: 9001071100 | B7: 51783.79 | C7: 21423.83 | K7: 9001070400 | L7: 17917.036 | M7: 1029.53 | N7: Yes | O7: 17866.172 | P7: 0 | Q7: 0 | U7: 0 | V7: 0 | Z7: 0 | AB7: 9001070300 | AC7: 33913.448 | AD7: 405270.6 | AE7: 16956.724 | AF7: 202635.3 | AG7: 0 | AH7: 202635.3 | AI7: 0 | AJ7: 2
A8: 9001071200 | B8: 45169.658 | C8: 4593.86 | K8: 9001070400 | L8: 17917.036 | M8: 1029.53 | N8: Yes | O8: 50.8641 | P8: 0 | Q8: 0 | U8: 0 | V8: 0 | Z8: 0 | AB8: 9001070400 | AC8: 53751.107 | AD8: 3088.59 | AE8: 17917.036 | AF8: 1029.53 | AG8: 380.24 | AH8: 649.29 | AI8: 3 | AJ8: 6
A9: 9001071300 | B9: 34389.421 | C9: 1572.32 | K9: 9001070500 | L9: 23101.569 | M9: 359.75 | N9: No | O9: 0 | P9: 359.75 | Q9: 0 | U9: 75 | V9: 7 | W9: 0 | X9: 7 | Y9: 0 | Z9: 284.75 | AB9: 9001070500 | AC9: 46203.137 | AD9: 719.5 | AE9: 23101.569 | AF9: 359.75 | AG9: 75 | AH9: 284.75 | AI9: 0 | AJ9: 7
A10: 9001071400 | B10: 38432.276 | C10: 3327.16 | K10: 9001070500 | L10: 23101.569 | M10: 359.75 | N10: Yes | O10: 23101.569 | P10: 0 | Q10: 0 | U10: 0 | V10: 0 | Z10: 0 | AB10: 9001070900 | AC10: 58349.917 | AD10: 8340.02 | AE10: 29174.959 | AF10: 4170.01 | AG10: 1302.6 | AH10: 2867.41 | AI10: 1 | AJ10: 12
A11: 9001071600 | B11: 24529.813 | C11: 1330.85 | K11: 9001070900 | L11: 29174.959 | M11: 4170.01 | N11: No | O11: 0 | P11: 4170.01 | Q11: 1 | R11: 0 | S11: 1 | T11: 0 | U11: 1302.6 | V11: 12 | W11: 4 | X11: 8 | Y11: 0 | Z11: 2867.41 | AB11: 9001071000 | AC11: 74498.698 | AD11: 28759 | AE11: 37249.349 | AF11: 14379.5 | AG11: 118.52 | AH11: 14260.98 | AI11: 1 | AJ11: 17
A12: 9001071900 | B12: 46534.636 | C12: 3620.23 | K12: 9001070900 | L12: 29174.959 | M12: 4170.01 | N12: Yes | O12: 29174.959 | P12: 0 | Q12: 0 | U12: 0 | V12: 0 | Z12: 0 | AB12: 9001071100 | AC12: 51783.79 | AD12: 21423.83 | AE12: 51783.79 | AF12: 21423.83 | AG12: 1246.62 | AH12: 20177.21 | AI12: 5 | AJ12: 19
A13: 9001073300 | B13: 49786.05 | C13: 21408.65 | K13: 9001071000 | L13: 37249.349 | M13: 14379.5 | N13: No | O13: 0 | P13: 14379.5 | Q13: 1 | R13: 1 | S13: 0 | T13: 0 | U13: 118.52 | V13: 17 | W13: 2 | X13: 14 | Y13: 1 | Z13: 14260.98 | AB13: 9001071200 | AC13: 90339.316 | AD13: 9187.72 | AE13: 45169.658 | AF13: 4593.86 | AG13: 954.34 | AH13: 3639.52 | AI13: 2 | AJ13: 21
A14: 9001073400 | B14: 53978.009 | C14: 48424.62 | K14: 9001071000 | L14: 37249.349 | M14: 14379.5 | N14: Yes | O14: 37249.349 | P14: 0 | Q14: 0 | U14: 0 | V14: 0 | Z14: 0 | AB14: 9001071300 | AC14: 68778.842 | AD14: 3144.64 | AE14: 34389.421 | AF14: 1572.32 | AG14: 12.03 | AH14: 1560.29 | AI14: 1 | AJ14: 12
A15: 9001073500 | B15: 38030.339 | C15: 7178.22 | K15: 9001071100 | L15: 51783.79 | M15: 21423.83 | N15: No | O15: 51783.79 | P15: 21423.83 | Q15: 5 | R15: 4 | S15: 1 | T15: 0 | U15: 1246.62 | V15: 19 | W15: 9 | X15: 10 | Y15: 0 | Z15: 20177.21 | AB15: 9001071400 | AC15: 38432.276 | AD15: 3327.16 | AE15: 38432.276 | AF15: 3327.16 | AG15: 927.04 | AH15: 2400.12 | AI15: 2 | AJ15: 15
A16: 9001073600 | B16: 24351.613 | C16: 846.37 | K16: 9001071200 | L16: 45169.658 | M16: 4593.86 | N16: No | O16: 0 | P16: 4593.86 | Q16: 2 | R16: 2 | S16: 0 | T16: 0 | U16: 954.34 | V16: 21 | W16: 8 | X16: 13 | Y16: 0 | Z16: 3639.52 | AB16: 9001071600 | AC16: 49059.626 | AD16: 2661.7 | AE16: 24529.813 | AF16: 1330.85 | AG16: 0 | AH16: 1330.85 | AI16: 0 | AJ16: 8
A17: 9001073700 | B17: 64008.136 | C17: 24518.83 | K17: 9001071200 | L17: 45169.658 | M17: 4593.86 | N17: Yes | O17: 45169.658 | P17: 0 | Q17: 0 | U17: 0 | V17: 0 | Z17: 0 | AB17: 9001071900 | AC17: 139603.91 | AD17: 10860.69 | AE17: 46534.636 | AF17: 3620.23 | AG17: 404.3 | AH17: 3215.93 | AI17: 2 | AJ17: 11
A18: 9001073800 | B18: 25510.302 | C18: 2512.29 | K18: 9001071300 | L18: 34389.421 | M18: 1572.32 | N18: No | O18: 0 | P18: 1572.32 | Q18: 1 | R18: 0 | S18: 1 | T18: 0 | U18: 12.03 | V18: 12 | W18: 2 | X18: 10 | Y18: 0 | Z18: 1560.29 | AB18: 9001073300 | AC18: 99572.101 | AD18: 42817.3 | AE18: 49786.05 | AF18: 21408.65 | AG18: 1427.69 | AH18: 19980.96 | AI18: 3 | AJ18: 22
A19: 9001073900 | B19: 35070.079 | C19: 106775.64 | K19: 9001071300 | L19: 34389.421 | M19: 1572.32 | N19: Yes | O19: 34389.421 | P19: 0 | Q19: 0 | U19: 0 | V19: 0 | Z19: 0 | AB19: 9001073400 | AC19: 107956.02 | AD19: 96849.24 | AE19: 53978.009 | AF19: 48424.62 | AG19: 4874.45 | AH19: 43550.17 | AI19: 9 | AJ19: 29
A20: 9001074000 | B20: 26942.261 | C20: 13413.06 | K20: 9001071400 | L20: 38432.276 | M20: 3327.16 | N20: No | O20: 38432.276 | P20: 3327.16 | Q20: 2 | R20: 1 | S20: 1 | T20: 0 | U20: 927.04 | V20: 15 | W20: 2 | X20: 13 | Y20: 0 | Z20: 2400.12 | AB20: 9001073500 | AC20: 76060.678 | AD20: 14356.44 | AE20: 38030.339 | AF20: 7178.22 | AG20: 501.38 | AH20: 6676.84 | AI20: 5 | AJ20: 17
A21: 9001074300 | B21: 51618.49 | C21: 8289.77 | K21: 9001071600 | L21: 24529.813 | M21: 1330.85 | N21: No | O21: 0 | P21: 1330.85 | Q21: 0 | U21: 0 | V21: 8 | W21: 1 | X21: 7 | Y21: 0 | Z21: 1330.85 | AB21: 9001073600 | AC21: 48703.226 | AD21: 1692.74 | AE21: 24351.613 | AF21: 846.37 | AG21: 134.5 | AH21: 711.87 | AI21: 1 | AJ21: 7
A22: 9001074400 | B22: 54299.358 | C22: 20133.35 | K22: 9001071600 | L22: 24529.813 | M22: 1330.85 | N22: Yes | O22: 24529.813 | P22: 0 | Q22: 0 | U22: 0 | V22: 0 | Z22: 0 | AB22: 9001073700 | AC22: 192024.41 | AD22: 73556.49 | AE22: 64008.136 | AF22: 24518.83 | AG22: 3732.6 | AH22: 20786.23 | AI22: 3 | AJ22: 29
A23: 9001257200 | B23: 46248.605 | C23: 7200.74 | K23: 9001071900 | L23: 46534.636 | M23: 3620.23 | N23: No | O23: 0 | P23: 230 | Q23: 0 | U23: 0 | V23: 1 | W23: 1 | X23: 0 | Y23: 0 | Z23: 230 | AB23: 9001073800 | AC23: 51020.603 | AD23: 5024.58 | AE23: 25510.302 | AF23: 2512.29 | AG23: 2.34 | AH23: 447.45 | AI23: 1 | AJ23: 4
A24: 9009120200 | B24: 98996.496 | C24: 18704.38 | K24: 9001071900 | L24: 46534.636 | M24: 3620.23 | N24: No | O24: 0 | P24: 3390.23 | Q24: 2 | R24: 2 | S24: 0 | T24: 0 | U24: 404.3 | V24: 10 | W24: 3 | X24: 6 | Y24: 1 | Z24: 2985.93 | AB24: 9001073900 | AC24: 70140.158 | AD24: 213551.28 | AE24: 35070.079 | AF24: 106775.64 | AG24: 170.07 | AH24: 106605.57 | AI24: 2 | AJ24: 24
A25: 9009140200 | B25: 5569.7997 | C25: 0 | K25: 9001071900 | L25: 46534.636 | M25: 3620.23 | N25: Yes | O25: 46534.636 | P25: 0 | Q25: 0 | U25: 0 | V25: 0 | Z25: 0 | AB25: 9001074000 | AC25: 53884.523 | AD25: 26826.12 | AE25: 26942.261 | AF25: 13413.06 | AG25: 183.09 | AH25: 13229.97 | AI25: 1 | AJ25: 15
A26: 9009140300 | B26: 27566.795 | C26: 2174.45 | K26: 9001073300 | L26: 49786.05 | M26: 21408.65 | N26: No | O26: 0 | P26: 21408.65 | Q26: 3 | R26: 3 | S26: 0 | T26: 0 | U26: 1427.69 | V26: 22 | W26: 19 | X26: 2 | Y26: 1 | Z26: 19980.96 | AB26: 9001074300 | AC26: 154855.47 | AD26: 24869.31 | AE26: 51618.49 | AF26: 8289.77 | AG26: 550.87 | AH26: 7738.9 | AI26: 2 | AJ26: 26
A27: 9009140500 | B27: 40619.57 | C27: 2256.95 | K27: 9001073300 | L27: 49786.05 | M27: 21408.65 | N27: Yes | O27: 49786.05 | P27: 0 | Q27: 0 | U27: 0 | V27: 0 | Z27: 0 | AB27: 9001074400 | AC27: 108598.72 | AD27: 40266.7 | AE27: 54299.358 | AF27: 20133.35 | AG27: 3501.35 | AH27: 6632 | AI27: 9 | AJ27: 25
A28: 9009140600 | B28: 52288.773 | C28: 3999.65 | K28: 9001073400 | L28: 53978.009 | M28: 48424.62 | N28: No | O28: 0 | P28: 48424.62 | Q28: 9 | R28: 7 | S28: 2 | T28: 0 | U28: 4874.45 | V28: 29 | W28: 7 | X28: 22 | Y28: 0 | Z28: 43550.17 | AB28: 9001257200 | AC28: 46248.605 | AD28: 7200.74 | AE28: 46248.605 | AF28: 7200.74 | AG28: 481.19 | AH28: 6719.55 | AI28: 1 | AJ28: 15
A29: 9009141500 | B29: 89595.167 | C29: 47450.57 | K29: 9001073400 | L29: 53978.009 | M29: 48424.62 | N29: Yes | O29: 53978.009 | P29: 0 | Q29: 0 | U29: 0 | V29: 0 | Z29: 0 | AB29: 9009120200 | AC29: 296989.49 | AD29: 56113.14 | AE29: 98996.496 | AF29: 18704.38 | AG29: 9845.58 | AH29: 8858.8 | AI29: 16 | AJ29: 9
A30: 9009141600 | B30: 59212.537 | C30: 10815.87 | K30: 9001073500 | L30: 38030.339 | M30: 7178.22 | N30: No | O30: 0 | P30: 7178.22 | Q30: 5 | R30: 4 | S30: 1 | T30: 0 | U30: 501.38 | V30: 17 | W30: 4 | X30: 13 | Y30: 0 | Z30: 6676.84 | AB30: 9009140200 | AC30: 11139.599 | AD30: 0 | AE30: 5569.7997 | AF30: 0 | AG30: 0 | AH30: 0 | AI30: 0 | AJ30: 0
A31: 9009142300 | B31: 53392.116 | C31: 10400.34 | K31: 9001073500 | L31: 38030.339 | M31: 7178.22 | N31: Yes | O31: 38030.339 | P31: 0 | Q31: 0 | U31: 0 | V31: 0 | Z31: 0 | AB31: 9009140300 | AC31: 55133.59 | AD31: 4348.9 | AE31: 27566.795 | AF31: 2174.45 | AG31: 284.16 | AH31: 1890.29 | AI31: 1 | AJ31: 10
A32: 9009142400 | B32: 54491.193 | C32: 6815.37 | K32: 9001073600 | L32: 24351.613 | M32: 846.37 | N32: No | O32: 0 | P32: 846.37 | Q32: 1 | R32: 1 | S32: 0 | T32: 0 | U32: 134.5 | V32: 7 | W32: 1 | X32: 6 | Y32: 0 | Z32: 711.87 | AB32: 9009140500 | AC32: 81239.139 | AD32: 4513.9 | AE32: 40619.57 | AF32: 2256.95 | AG32: 1274.28 | AH32: 982.67 | AI32: 4 | AJ32: 5
A33: 9009142500 | B33: 65008.415 | C33: 7352.41 | K33: 9001073600 | L33: 24351.613 | M33: 846.37 | N33: Yes | O33: 24351.613 | P33: 0 | Q33: 0 | U33: 0 | V33: 0 | Z33: 0 | AB33: 9009140600 | AC33: 104577.55 | AD33: 7999.3 | AE33: 52288.773 | AF33: 3999.65 | AG33: 352.22 | AH33: 2334.93 | AI33: 4 | AJ33: 13
A34: 9009142700 | B34: 84074.735 | C34: 29975.46 | K34: 9001073700 | L34: 64008.136 | M34: 24518.83 | N34: No | O34: 0 | P34: 24518.83 | Q34: 3 | R34: 3 | S34: 0 | T34: 0 | U34: 3732.6 | V34: 29 | W34: 13 | X34: 16 | Y34: 0 | Z34: 20786.23 | AB34: 9009141500 | AC34: 268785.5 | AD34: 142351.71 | AE34: 89595.167 | AF34: 47450.57 | AG34: 2901.52 | AH34: 27049.05 | AI34: 9 | AJ34: 53
A35: 9009165500 | B35: 68231.695 | C35: 42137.05 | K35: 9001073700 | L35: 64008.136 | M35: 24518.83 | N35: Yes | O35: 64008.136 | P35: 0 | Q35: 0 | U35: 0 | V35: 0 | Z35: 0 | AB35: 9009141600 | AC35: 118425.07 | AD35: 21631.74 | AE35: 59212.537 | AF35: 10815.87 | AG35: 484.3 | AH35: 10331.57 | AI35: 4 | AJ35: 18
K36: 9001073700 | L36: 64008.136 | M36: 24518.83 | N36: Yes | O36: 0 | P36: 0 | Q36: 0 | U36: 0 | V36: 0 | Z36: 0 | AB36: 9009142300 | AC36: 160176.35 | AD36: 31201.02 | AE36: 53392.116 | AF36: 10400.34 | AG36: 2968.24 | AH36: 7432.1 | AI36: 10 | AJ36: 17
K37: 9001073800 | L37: 25510.302 | M37: 2512.29 | N37: No | O37: 0 | P37: 2512.29 | Q37: 1 | R37: 1 | S37: 0 | T37: 0 | U37: 2.34 | V37: 4 | W37: 1 | X37: 3 | Y37: 0 | Z37: 447.45 | AB37: 9009142400 | AC37: 108982.39 | AD37: 13630.74 | AE37: 54491.193 | AF37: 6815.37 | AG37: 2179.8 | AH37: 4635.57 | AI37: 6 | AJ37: 18
K38: 9001073800 | L38: 25510.302 | M38: 2512.29 | N38: Yes | O38: 25510.302 | P38: 0 | Q38: 0 | U38: 0 | V38: 0 | Z38: 0 | AB38: 9009142500 | AC38: 195025.24 | AD38: 22057.23 | AE38: 65008.414 | AF38: 7352.41 | AG38: 2183.98 | AH38: 5168.43 | AI38: 9 | AJ38: 8
K39: 9001073900 | L39: 35070.079 | M39: 106775.64 | N39: No | O39: 0 | P39: 106775.64 | Q39: 2 | R39: 2 | S39: 0 | T39: 0 | U39: 170.07 | V39: 24 | W39: 5 | X39: 17 | Y39: 2 | Z39: 106605.57 | AB39: 9009142700 | AC39: 168149.47 | AD39: 59950.92 | AE39: 84074.735 | AF39: 29975.46 | AG39: 8295.25 | AH39: 15680.21 | AI39: 8 | AJ39: 20
K40: 9001073900 | L40: 35070.079 | M40: 106775.64 | N40: Yes | O40: 35070.079 | P40: 0 | Q40: 0 | U40: 0 | V40: 0 | Z40: 0 | AB40: 9009165500 | AC40: 272926.78 | AD40: 168548.2 | AE40: 68231.695 | AF40: 42137.05 | AG40: 4512.21 | AH40: 37624.84 | AI40: 13 | AJ40: 21
...

Sheet HESParticipationStats
A1: id | B1: tract | C1: Geographic Area Name | D1: Estimate!!Occupied housing units!!Occupied housing units!!HOUSEHOLD INCOME IN THE PAST 12 MONTHS (IN 2019 INFLATION-ADJUSTED DOLLARS)!!Median household income (dollars) 250000 = 250000+ | E1: Estimate!!HOUSEHOLDS BY TYPE!!Total households!!Average household size | F1: Household Size Adjusted income = (Household Income)/(Household Size)^N N =1/2 | G1: adjusted income (thousands of $) | H1: incomee percentile | I1: Income Rank | J1: reverse income percentile | K1: REVERSE income Rank | L1: median census housing cost | M1: housing cost as percentage of income | N1: Housing cost rank as fraction of median income percentile | O1: housing cost rank | P1: Housing cost percentile | Q1: Housing cost rank on absolute housing cost | R1: Combined affluence rank | S1: CTRUCA.Primary RUCA Code 2010 | T1: CTRUCA.Secondary RUCA Code, 2010 (see errata) | U1: CTRUCA.Tract Population, 2010 | V1: CTRUCA.Land Area (square miles), 2010 | W1: CTRUCA.Population Density (per square mile), 2010 | X1: rural rank | Y1: racialdiversitytable.POC population | Z1: racialdiversitytable.POC % of population | AA1: racialdiversitytable.percentile rank | AB1: racial diversity index | AC1: composit index | AD1: rounded composite | AE1: Income <=60 %SMI? | AF1: Income <=80% SMI | AG1: HESReportTable.CLM $ Collected | AH1: HESReportTable.Incentive Disbursements | AI1: HESReportTable.HES Total Units | AJ1: HESReportTable.HES Single Family | AK1: HESReportTable.HES 2-4 Units | AL1: HESReportTable.HES >4 Units | AM1: HESReportTable.Incentives | AN1: HESReportTable.HESIE Total Units | AO1: HESReportTable.HESIE Single Family | AP1: HESReportTable.HESIE 2-4 Units2 | AQ1: HESReportTable.HESIE >4 Units | AR1: HESReportTable.HESIE Incentives | AX1: Income <=60 %SMI? | AY1: (All)
A2: 1400000US09001055100 | B2: 9001055100 | C2: Census Tract 551, Fairfield County, Connecticut | D2: 202500 | E2: 2.93 | F2: 118301.76 | G2: 118.302 | H2: 0.972 | I2: 5 | J2: 0.028 | K2: 1 | L2: 4000 | M2: 0.40574205 | N2: 0.693 | O2: 4 | P2: 0.011 | Q2: 1 | R2: 1 | S2: 1 | T2: 1 | U2: 5807 | V2: 13.373285 | W2: 434.2239 | X2: 1 | Y2: 942 | Z2: 16.875672 | AA2: 0.657 | AB2: 4 | AC2: 2.5 | AD2: 3 | AE2: No | AF2: No | AG2: 394.428 | AH2: 0 | AI2: 0 | AM2: 0 | AN2: 0 | AR2: 0 | AX2: Income <=80% SMI | AY2: (All)
A3: 1400000US09001055200 | B3: 9001055200 | C3: Census Tract 552, Fairfield County, Connecticut | D3: 247361 | E3: 3.05 | F3: 141638.5 | G3: 141.638 | H3: 0.992 | I3: 5 | J3: 0.008 | K3: 1 | L3: 3750 | M3: 0.31771023 | N3: 0.27 | O3: 2 | P3: 0.018 | Q3: 1 | R3: 1 | S3: 1 | T3: 1 | U3: 4372 | V3: 6.4253919 | W3: 680.42542 | X3: 1 | Y3: 241 | Z3: 5.1222104 | AA3: 0.143 | AB3: 1 | AC3: 1 | AD3: 1 | AE3: No | AF3: No | AG3: 887.5106 | AH3: 0 | AI3: 0 | AM3: 0 | AN3: 0 | AR3: 0 | BF3: BIPOC INDEX | BG3: Sum of HESReportTable.CLM $ Collected | BH3: Sum of HESReportTable.Incentive Disbursements | BI3: Sum of HESReportTable.HES Total Units | BJ3: Sum of HESReportTable.Incentives | BK3: Sum of HESReportTable.HESIE Total Units | BL3: Sum of HESReportTable.HESIE Incentives
A4: 1400000US09001060100 | B4: 9001060100 | C4: Census Tract 601, Fairfield County, Connecticut | D4: 139000 | E4: 2.65 | F4: 85387.021 | G4: 85.387 | H4: 0.91 | I4: 5 | J4: 0.09 | K4: 1 | L4: 2313 | M4: 0.32506111 | N4: 0.33 | O4: 2 | P4: 0.111 | Q4: 1 | R4: 1 | S4: 1 | T4: 1 | U4: 4152 | V4: 1.5389894 | W4: 2697.8744 | X4: 1 | Y4: 333 | Z4: 7.5441776 | AA4: 0.269 | AB4: 2 | AC4: 1.5 | AD4: 2 | AE4: No | AF4: No | AG4: 0 | AH4: 0 | AI4: 0 | AM4: 0 | AN4: 0 | AR4: 0 | AX4: Row Labels | AY4: Sum of HESReportTable.CLM $ Collected | AZ4: Sum of HESReportTable.Incentive Disbursements | BA4: Sum of HESReportTable.HES Total Units | BB4: Sum of HESReportTable.Incentives | BC4: Sum of HESReportTable.HESIE Total Units | BD4: Sum of HESReportTable.HESIE Incentives | BF4: 1 | BG4: 1233439.3 | BH4: 355917.5 | BI4: 315 | BJ4: 256816.2 | BK4: 37 | BL4: 96701.3
A5: 1400000US09001060100 | B5: 9001060100 | C5: Census Tract 601, Fairfield County, Connecticut | D5: 139000 | E5: 2.65 | F5: 85387.021 | G5: 85.387 | H5: 0.91 | I5: 5 | J5: 0.09 | K5: 1 | L5: 2313 | M5: 0.32506111 | N5: 0.33 | O5: 2 | P5: 0.111 | Q5: 1 | R5: 1 | S5: 1 | T5: 1 | U5: 4152 | V5: 1.5389894 | W5: 2697.8744 | X5: 1 | Y5: 333 | Z5: 7.5441776 | AA5: 0.269 | AB5: 2 | AC5: 1.5 | AD5: 2 | AE5: No | AF5: No | AG5: 58128.329 | AH5: 19857.8 | AI5: 16 | AJ5: 15 | AK5: 1 | AL5: 0 | AM5: 15652.21 | AN5: 2 | AO5: 2 | AP5: 0 | AQ5: 0 | AR5: 4205.59 | AX5: 9001055100 | AY5: 394.428 | AZ5: 0 | BA5: 0 | BB5: 0 | BC5: 0 | BD5: 0 | BF5: 2 | BG5: 1849524.4 | BH5: 641461.43 | BI5: 541 | BJ5: 476590.31 | BK5: 99 | BL5: 156221.12
A6: 1400000US09001060100 | B6: 9001060100 | C6: Census Tract 601, Fairfield County, Connecticut | D6: 139000 | E6: 2.65 | F6: 85387.021 | G6: 85.387 | H6: 0.91 | I6: 5 | J6: 0.09 | K6: 1 | L6: 2313 | M6: 0.32506111 | N6: 0.33 | O6: 2 | P6: 0.111 | Q6: 1 | R6: 1 | S6: 1 | T6: 1 | U6: 4152 | V6: 1.5389894 | W6: 2697.8744 | X6: 1 | Y6: 333 | Z6: 7.5441776 | AA6: 0.269 | AB6: 2 | AC6: 1.5 | AD6: 2 | AE6: No | AF6: No | AG6: 0 | AH6: 0 | AI6: 0 | AM6: 0 | AN6: 0 | AR6: 0 | AX6: 9001055200 | AY6: 887.5106 | AZ6: 0 | BA6: 0 | BB6: 0 | BC6: 0 | BD6: 0 | BF6: 3 | BG6: 3153797.1 | BH6: 1288734.7 | BI6: 924 | BJ6: 705952.43 | BK6: 273 | BL6: 357722.25
A7: 1400000US09001060200 | B7: 9001060200 | C7: Census Tract 602, Fairfield County, Connecticut | D7: 126838 | E7: 2.81 | F7: 75665.207 | G7: 75.665 | H7: 0.855 | I7: 5 | J7: 0.145 | K7: 1 | L7: 2452 | M7: 0.38887094 | N7: 0.659 | O7: 4 | P7: 0.082 | Q7: 1 | R7: 1 | S7: 1 | T7: 1 | U7: 4164 | V7: 1.5648428 | W7: 2660.9702 | X7: 1 | Y7: 523 | Z7: 11.992662 | AA7: 0.491 | AB7: 3 | AC7: 2 | AD7: 2 | AE7: No | AF7: No | AG7: 78630.955 | AH7: 29656.58 | AI7: 26 | AJ7: 26 | AK7: 0 | AL7: 0 | AM7: 20186.77 | AN7: 3 | AO7: 3 | AP7: 0 | AQ7: 0 | AR7: 9469.81 | AX7: 9001060100 | AY7: 58128.329 | AZ7: 19857.8 | BA7: 16 | BB7: 15652.21 | BC7: 2 | BD7: 4205.59 | BF7: 4 | BG7: 2680511.7 | BH7: 1554367.5 | BI7: 604 | BJ7: 407795.79 | BK7: 365 | BL7: 1136526.7
A8: 1400000US09001060300 | B8: 9001060300 | C8: Census Tract 603, Fairfield County, Connecticut | D8: 195250 | E8: 2.92 | F8: 114261.42 | G8: 114.261 | H8: 0.965 | I8: 5 | J8: 0.035 | K8: 1 | L8: 3341 | M8: 0.35087959 | N8: 0.484 | O8: 3 | P8: 0.03 | Q8: 1 | R8: 1 | S8: 1 | T8: 1 | U8: 4088 | V8: 4.5106101 | W8: 906.30755 | X8: 1 | Y8: 260 | Z8: 6.5689742 | AA8: 0.221 | AB8: 2 | AC8: 1.5 | AD8: 2 | AE8: No | AF8: No | AG8: 92872.917 | AH8: 19540.71 | AI8: 15 | AJ8: 15 | AK8: 0 | AL8: 0 | AM8: 11061.91 | AN8: 2 | AO8: 2 | AP8: 0 | AQ8: 0 | AR8: 8478.8 | AX8: 9001060200 | AY8: 78630.955 | AZ8: 29656.58 | BA8: 26 | BB8: 20186.77 | BC8: 3 | BD8: 9469.81 | BF8: 5 | BG8: 3212520.4 | BH8: 1176273.2 | BI8: 543 | BJ8: 310393.14 | BK8: 730 | BL8: 846505.08
A9: 1400000US09001060400 | B9: 9001060400 | C9: Census Tract 604, Fairfield County, Connecticut | D9: 247169 | E9: 2.83 | F9: 146926.72 | G9: 146.927 | H9: 1 | I9: 5 | J9: 0 | K9: 0 | L9: 3810 | M9: 0.31117553 | N9: 0.229 | O9: 2 | P9: 0.014 | Q9: 1 | R9: 1 | S9: 1 | T9: 1 | U9: 4443 | V9: 8.6430864 | W9: 514.05248 | X9: 1 | Y9: 233 | Z9: 5.1548673 | AA9: 0.144 | AB9: 1 | AC9: 1 | AD9: 1 | AE9: No | AF9: No | AG9: 158569.58 | AH9: 16361.63 | AI9: 15 | AJ9: 15 | AK9: 0 | AL9: 0 | AM9: 16361.63 | AN9: 0 | AR9: 0 | AX9: 9001060300 | AY9: 92872.917 | AZ9: 19540.71 | BA9: 15 | BB9: 11061.91 | BC9: 2 | BD9: 8478.8
A10: 1400000US09001060500 | B10: 9001060500 | C10: Census Tract 605, Fairfield County, Connecticut | D10: 216500 | E10: 3.17 | F10: 121598.51 | G10: 121.599 | H10: 0.973 | I10: 5 | J10: 0.027 | K10: 1 | L10: 3418 | M10: 0.33730675 | N10: 0.407 | O10: 3 | P10: 0.026 | Q10: 1 | R10: 1 | S10: 1 | T10: 1 | U10: 2841 | V10: 2.1100526 | W10: 1346.4119 | X10: 1 | Y10: 162 | Z10: 5.865315 | AA10: 0.182 | AB10: 1 | AC10: 1 | AD10: 1 | AE10: No | AF10: No | AG10: 71345.135 | AH10: 7351.8 | AI10: 13 | AJ10: 13 | AK10: 0 | AL10: 0 | AM10: 7351.8 | AN10: 0 | AR10: 0 | AX10: 9001060400 | AY10: 158569.58 | AZ10: 16361.63 | BA10: 15 | BB10: 16361.63 | BC10: 0 | BD10: 0
A11: 1400000US09001060600 | B11: 9001060600 | C11: Census Tract 606, Fairfield County, Connecticut | D11: 174712 | E11: 2.24 | F11: 116734.37 | G11: 116.734 | H11: 0.969 | I11: 5 | J11: 0.031 | K11: 1 | L11: 2525 | M11: 0.25956367 | N11: 0.032 | O11: 1 | P11: 0.075 | Q11: 1 | R11: 1 | S11: 1 | T11: 1 | U11: 2336 | V11: 1.1912198 | W11: 1961.0151 | X11: 1 | Y11: 212 | Z11: 9.1934085 | AA11: 0.361 | AB11: 2 | AC11: 1.5 | AD11: 2 | AE11: No | AF11: No | AG11: 73188.417 | AH11: 6296 | AI11: 9 | AJ11: 9 | AK11: 0 | AL11: 0 | AM11: 6296 | AN11: 0 | AR11: 0 | AX11: 9001060500 | AY11: 71345.135 | AZ11: 7351.8 | BA11: 13 | BB11: 7351.8 | BC11: 0 | BD11: 0
A12: 1400000US09001060700 | B12: 9001060700 | C12: Census Tract 607, Fairfield County, Connecticut | D12: 180694 | E12: 3.01 | F12: 104150.29 | G12: 104.15 | H12: 0.953 | I12: 5 | J12: 0.047 | K12: 1 | L12: 2864 | M12: 0.32998468 | N12: 0.358 | O12: 2 | P12: 0.05 | Q12: 1 | R12: 1 | S12: 1 | T12: 1 | U12: 7675 | V12: 2.0484516 | W12: 3746.7325 | X12: 1 | Y12: 575 | Z12: 7.2037083 | AA12: 0.251 | AB12: 2 | AC12: 1.5 | AD12: 2 | AE12: No | AF12: No | AG12: 98856.621 | AH12: 8336.04 | AI12: 15 | AJ12: 15 | AK12: 0 | AL12: 0 | AM12: 8336.04 | AN12: 0 | AR12: 0 | AX12: 9001060600 | AY12: 73188.417 | AZ12: 6296 | BA12: 9 | BB12: 6296 | BC12: 0 | BD12: 0
A13: 1400000US09001060800 | B13: 9001060800 | C13: Census Tract 608, Fairfield County, Connecticut | D13: 171250 | E13: 2.73 | F13: 103645.21 | G13: 103.645 | H13: 0.952 | I13: 5 | J13: 0.048 | K13: 1 | L13: 3043 | M13: 0.35231728 | N13: 0.492 | O13: 3 | P13: 0.044 | Q13: 1 | R13: 1 | S13: 1 | T13: 1 | U13: 2139 | V13: 0.54970564 | W13: 3891.1735 | X13: 1 | Y13: 154 | Z13: 7.3020389 | AA13: 0.256 | AB13: 2 | AC13: 1.5 | AD13: 2 | AE13: No | AF13: No | AG13: 39085.891 | AH13: 4387.52 | AI13: 7 | AJ13: 7 | AK13: 0 | AL13: 0 | AM13: 4254.42 | AN13: 1 | AO13: 1 | AP13: 0 | AQ13: 0 | AR13: 133.1 | AX13: 9001060700 | AY13: 98856.621 | AZ13: 8336.04 | BA13: 15 | BB13: 8336.04 | BC13: 0 | BD13: 0
A14: 1400000US09001060900 | B14: 9001060900 | C14: Census Tract 609, Fairfield County, Connecticut | D14: 140278 | E14: 2.88 | F14: 82659.604 | G14: 82.66 | H14: 0.896 | I14: 5 | J14: 0.104 | K14: 1 | L14: 2698 | M14: 0.39167862 | N14: 0.667 | O14: 4 | P14: 0.059 | Q14: 1 | R14: 1 | S14: 1 | T14: 1 | U14: 2447 | V14: 0.57765634 | W14: 4236.0826 | X14: 1 | Y14: 128 | Z14: 4.8338369 | AA14: 0.133 | AB14: 1 | AC14: 1 | AD14: 1 | AE14: No | AF14: No | AG14: 48889.4 | AH14: 30036.3 | AI14: 13 | AJ14: 13 | AK14: 0 | AL14: 0 | AM14: 10016.58 | AN14: 1 | AO14: 1 | AP14: 0 | AQ14: 0 | AR14: 20019.72 | AX14: 9001060800 | AY14: 39085.891 | AZ14: 4387.52 | BA14: 7 | BB14: 4254.42 | BC14: 1 | BD14: 133.1 | BF14: BIPOC INDEX
A15: 1400000US09001061000 | B15: 9001061000 | C15: Census Tract 610, Fairfield County, Connecticut | D15: 78844 | E15: 2.54 | F15: 49471.126 | G15: 49.471 | H15: 0.461 | I15: 3 | J15: 0.539 | K15: 3 | L15: 1741 | M15: 0.42230695 | N15: 0.734 | O15: 4 | P15: 0.288 | Q15: 2 | R15: 3 | S15: 1 | T15: 1 | U15: 3816 | V15: 1.2856179 | W15: 2968.2225 | X15: 1 | Y15: 547 | Z15: 14.065312 | AA15: 0.572 | AB15: 3 | AC15: 3 | AD15: 3 | AE15: No | AF15: No | AG15: 73580.641 | AH15: 75486.32 | AI15: 17 | AJ15: 17 | AK15: 0 | AL15: 0 | AM15: 14143.73 | AN15: 3 | AO15: 3 | AP15: 0 | AQ15: 0 | AR15: 2267.59 | AX15: 9001060900 | AY15: 48889.4 | AZ15: 30036.3 | BA15: 13 | BB15: 10016.58 | BC15: 1 | BD15: 20019.72 | BF15: 1 | BG15: =BG4/SUM(BG$4:BG$8) -> 0.10168676 | BH15: =BH4/SUM(BH$4:BH$8) -> 0.07094577 | BI15: =BI4/SUM(BI$4:BI$8) -> 0.10761872 | BJ15: =BJ4/SUM(BJ$4:BJ$8) -> 0.11903152 | BK15: =BK4/SUM(BK$4:BK$8) -> 0.024601064 | BL15: =BL4/SUM(BL$4:BL$8) -> 0.037283486
A16: 1400000US09001061100 | B16: 9001061100 | C16: Census Tract 611, Fairfield County, Connecticut | D16: 163438 | E16: 2.99 | F16: 94518.636 | G16: 94.519 | H16: 0.934 | I16: 5 | J16: 0.066 | K16: 1 | L16: 2692 | M16: 0.34177387 | N16: 0.429 | O16: 3 | P16: 0.06 | Q16: 1 | R16: 1 | S16: 1 | T16: 1 | U16: 3771 | V16: 1.0451898 | W16: 3607.9572 | X16: 1 | Y16: 183 | Z16: 4.7631442 | AA16: 0.126 | AB16: 1 | AC16: 1 | AD16: 1 | AE16: No | AF16: No | AG16: 67549.059 | AH16: 4173.07 | AI16: 12 | AJ16: 12 | AK16: 0 | AL16: 0 | AM16: 4173.07 | AN16: 0 | AR16: 0 | AX16: 9001061000 | AY16: 73580.641 | AZ16: 75486.32 | BA16: 17 | BB16: 14143.73 | BC16: 3 | BD16: 2267.59 | BF16: 2 | BG16: =BG5/SUM(BG$4:BG$8) -> 0.15247782 | BH16: =BH5/SUM(BH$4:BH$8) -> 0.12786383 | BI16: =BI5/SUM(BI$4:BI$8) -> 0.18483088 | BJ16: =BJ5/SUM(BJ$4:BJ$8) -> 0.22089443 | BK16: =BK5/SUM(BK$4:BK$8) -> 0.065824468 | BL16: =BL5/SUM(BL$4:BL$8) -> 0.060231537
A17: 1400000US09001061200 | B17: 9001061200 | C17: Census Tract 612, Fairfield County, Connecticut | D17: 81667 | E17: 2.88 | F17: 48122.741 | G17: 48.123 | H17: 0.433 | I17: 3 | J17: 0.567 | K17: 3 | L17: 1853 | M17: 0.46206844 | N17: 0.801 | O17: 5 | P17: 0.23 | Q17: 2 | R17: 3 | S17: 1 | T17: 1 | U17: 2186 | V17: 0.30555701 | W17: 7154.1477 | X17: 1 | Y17: 661 | Z17: 26.397764 | AA17: 0.844 | AB17: 5 | AC17: 4 | AD17: 4 | AE17: No | AF17: No | AG17: 35405.152 | AH17: 19213.03 | AI17: 12 | AJ17: 9 | AK17: 3 | AL17: 0 | AM17: 5648.47 | AN17: 1 | AO17: 1 | AP17: 0 | AQ17: 0 | AR17: 13564.56 | AX17: 9001061100 | AY17: 67549.059 | AZ17: 4173.07 | BA17: 12 | BB17: 4173.07 | BC17: 0 | BD17: 0 | BF17: 3 | BG17: =BG6/SUM(BG$4:BG$8) -> 0.2600042 | BH17: =BH6/SUM(BH$4:BH$8) -> 0.25688614 | BI17: =BI6/SUM(BI$4:BI$8) -> 0.31568159 | BJ17: =BJ6/SUM(BJ$4:BJ$8) -> 0.32720128 | BK17: =BK6/SUM(BK$4:BK$8) -> 0.18151596 | BL17: =BL6/SUM(BL$4:BL$8) -> 0.13792092
A18: 1400000US09001061300 | B18: 9001061300 | C18: Census Tract 613, Fairfield County, Connecticut | D18: 90913 | E18: 2.74 | F18: 54922.552 | G18: 54.923 | H18: 0.557 | I18: 3 | J18: 0.443 | K18: 3 | L18: 1857 | M18: 0.40573497 | N18: 0.692 | O18: 4 | P18: 0.229 | Q18: 2 | R18: 3 | S18: 1 | T18: 1 | U18: 2954 | V18: 0.48268332 | W18: 6119.9546 | X18: 1 | Y18: 571 | Z18: 18.366034 | AA18: 0.699 | AB18: 4 | AC18: 3.5 | AD18: 4 | AE18: No | AF18: No | AG18: 51750.384 | AH18: 7224.19 | AI18: 9 | AJ18: 8 | AK18: 1 | AL18: 0 | AM18: 4853.85 | AN18: 3 | AO18: 3 | AP18: 0 | AQ18: 0 | AR18: 2370.34 | AX18: 9001061200 | AY18: 35405.152 | AZ18: 19213.03 | BA18: 12 | BB18: 5648.47 | BC18: 1 | BD18: 13564.56 | BF18: 4 | BG18: =BG7/SUM(BG$4:BG$8) -> 0.22098578 | BH18: =BH7/SUM(BH$4:BH$8) -> 0.30983528 | BI18: =BI7/SUM(BI$4:BI$8) -> 0.20635463 | BJ18: =BJ7/SUM(BJ$4:BJ$8) -> 0.18900892 | BK18: =BK7/SUM(BK$4:BK$8) -> 0.24268617 | BL18: =BL7/SUM(BL$4:BL$8) -> 0.4381914
A19: 1400000US09001061400 | B19: 9001061400 | C19: Census Tract 614, Fairfield County, Connecticut | D19: 91467 | E19: 2.6 | F19: 56725.425 | G19: 56.725 | H19: 0.594 | I19: 3 | J19: 0.406 | K19: 3 | L19: 1873 | M19: 0.39622444 | N19: 0.677 | O19: 4 | P19: 0.219 | Q19: 2 | R19: 3 | S19: 1 | T19: 1 | U19: 2736 | V19: 0.62377084 | W19: 4386.2262 | X19: 1 | Y19: 858 | Z19: 27.86619 | AA19: 0.864 | AB19: 5 | AC19: 4 | AD19: 4 | AE19: No | AF19: No | AG19: 47281.252 | AH19: 5299.19 | AI19: 6 | AJ19: 5 | AK19: 1 | AL19: 0 | AM19: 3377.69 | AN19: 2 | AO19: 2 | AP19: 0 | AQ19: 0 | AR19: 1921.5 | AX19: 9001061300 | AY19: 51750.384 | AZ19: 7224.19 | BA19: 9 | BB19: 4853.85 | BC19: 3 | BD19: 2370.34 | BF19: 5 | BG19: =BG8/SUM(BG$4:BG$8) -> 0.26484544 | BH19: =BH8/SUM(BH$4:BH$8) -> 0.23446897 | BI19: =BI8/SUM(BI$4:BI$8) -> 0.18551418 | BJ19: =BJ8/SUM(BJ$4:BJ$8) -> 0.14386385 | BK19: =BK8/SUM(BK$4:BK$8) -> 0.48537234 | BL19: =BL8/SUM(BL$4:BL$8) -> 0.32637266
A20: 1400000US09001061500 | B20: 9001061500 | C20: Census Tract 615, Fairfield County, Connecticut | D20: 148804 | E20: 2.76 | F20: 89569.482 | G20: 89.569 | H20: 0.923 | I20: 5 | J20: 0.077 | K20: 1 | L20: 2670 | M20: 0.35771112 | N20: 0.52 | O20: 3 | P20: 0.063 | Q20: 1 | R20: 1 | S20: 1 | T20: 1 | U20: 4692 | V20: 1.4069876 | W20: 3334.7842 | X20: 1 | Y20: 854 | Z20: 17.659222 | AA20: 0.68 | AB20: 4 | AC20: 2.5 | AD20: 3 | AE20: No | AF20: No | AG20: 0 | AH20: 0 | AI20: 0 | AM20: 0 | AN20: 0 | AR20: 0 | AX20: 9001061400 | AY20: 47281.252 | AZ20: 5299.19 | BA20: 6 | BB20: 3377.69 | BC20: 2 | BD20: 1921.5
A21: 1400000US09001061500 | B21: 9001061500 | C21: Census Tract 615, Fairfield County, Connecticut | D21: 148804 | E21: 2.76 | F21: 89569.482 | G21: 89.569 | H21: 0.923 | I21: 5 | J21: 0.077 | K21: 1 | L21: 2670 | M21: 0.35771112 | N21: 0.52 | O21: 3 | P21: 0.063 | Q21: 1 | R21: 1 | S21: 1 | T21: 1 | U21: 4692 | V21: 1.4069876 | W21: 3334.7842 | X21: 1 | Y21: 854 | Z21: 17.659222 | AA21: 0.68 | AB21: 4 | AC21: 2.5 | AD21: 3 | AE21: No | AF21: No | AG21: 104123.37 | AH21: 13917.12 | AI21: 18 | AJ21: 18 | AK21: 0 | AL21: 0 | AM21: 8101.4 | AN21: 4 | AO21: 4 | AP21: 0 | AQ21: 0 | AR21: 5815.72 | AX21: 9001061500 | AY21: 104123.37 | AZ21: 13917.12 | BA21: 18 | BB21: 8101.4 | BC21: 4 | BD21: 5815.72
A22: 1400000US09001061600 | B22: 9001061600 | C22: Census Tract 616, Fairfield County, Connecticut | D22: 129250 | E22: 2.57 | F22: 80623.935 | G22: 80.624 | H22: 0.883 | I22: 5 | J22: 0.117 | K22: 1 | L22: 2370 | M22: 0.35274885 | N22: 0.495 | O22: 3 | P22: 0.094 | Q22: 1 | R22: 1 | S22: 1 | T22: 1 | U22: 4964 | V22: 2.0182839 | W22: 2459.5153 | X22: 1 | Y22: 323 | Z22: 5.9583103 | AA22: 0.185 | AB22: 1 | AC22: 1 | AD22: 1 | AE22: No | AF22: No | AG22: 114122.91 | AH22: 10431.48 | AI22: 21 | AJ22: 20 | AK22: 1 | AL22: 0 | AM22: 9358.37 | AN22: 2 | AO22: 2 | AP22: 0 | AQ22: 0 | AR22: 1073.11 | AX22: 9001061600 | AY22: 114122.91 | AZ22: 10431.48 | BA22: 21 | BB22: 9358.37 | BC22: 2 | BD22: 1073.11
A23: 1400000US09001070100 | B23: 9001070100 | C23: Census Tract 701, Fairfield County, Connecticut | D23: 88021 | E23: 2.16 | F23: 59890.705 | G23: 59.891 | H23: 0.651 | I23: 4 | J23: 0.349 | K23: 2 | L23: 1489 | M23: 0.29834346 | N23: 0.16 | O23: 1 | P23: 0.49 | Q23: 3 | R23: 3 | S23: 1 | T23: 1 | U23: 5021 | V23: 0.65223159 | W23: 7698.1858 | X23: 1 | Y23: 764 | Z23: 15.384615 | AA23: 0.609 | AB23: 4 | AC23: 3.5 | AD23: 4 | AE23: No | AF23: No | AG23: 0 | AH23: 11088.15 | AI23: 14 | AJ23: 12 | AK23: 2 | AL23: 0 | AM23: 8716.18 | AN23: 5 | AO23: 4 | AP23: 1 | AQ23: 0 | AR23: 2371.97 | AX23: 9001070100 | AY23: 87876.711 | AZ23: 11088.15 | BA23: 14 | BB23: 8716.18 | BC23: 5 | BD23: 2371.97 | BF23: Income <= 80% SMI | BG23: Sum of HESReportTable.CLM $ Collected | BH23: Sum of HESReportTable.Incentive Disbursements | BI23: Sum of HESReportTable.HES Total Units | BJ23: Sum of HESReportTable.Incentives | BK23: Sum of HESReportTable.HESIE Total Units | BL23: Sum of HESReportTable.HESIE Incentives
A24: 1400000US09001070100 | B24: 9001070100 | C24: Census Tract 701, Fairfield County, Connecticut | D24: 88021 | E24: 2.16 | F24: 59890.705 | G24: 59.891 | H24: 0.651 | I24: 4 | J24: 0.349 | K24: 2 | L24: 1489 | M24: 0.29834346 | N24: 0.16 | O24: 1 | P24: 0.49 | Q24: 3 | R24: 3 | S24: 1 | T24: 1 | U24: 5021 | V24: 0.65223159 | W24: 7698.1858 | X24: 1 | Y24: 764 | Z24: 15.384615 | AA24: 0.609 | AB24: 4 | AC24: 3.5 | AD24: 4 | AE24: No | AF24: No | AG24: 87876.711 | AH24: 0 | AI24: 0 | AM24: 0 | AN24: 0 | AR24: 0 | AX24: 9001070200 | AY24: 45704.852 | AZ24: 2977.59 | BA24: 8 | BB24: 1549.83 | BC24: 8 | BD24: 1427.76 | BF24: No | BG24: 8556139.3 | BH24: 3529907.5 | BI24: 2478 | BJ24: 1932663.6 | BK24: 606 | BL24: 1361674
A25: 1400000US09001070200 | B25: 9001070200 | C25: Census Tract 702, Fairfield County, Connecticut | D25: 42688 | E25: 2.37 | F25: 27728.836 | G25: 27.729 | H25: 0.139 | I25: 1 | J25: 0.861 | K25: 5 | L25: 1292 | M25: 0.55912914 | N25: 0.897 | O25: 5 | P25: 0.662 | Q25: 4 | R25: 5 | S25: 1 | T25: 1 | U25: 4052 | V25: 0.32567255 | W25: 12441.945 | X25: 1 | Y25: 665 | Z25: 17.139175 | AA25: 0.661 | AB25: 4 | AC25: 4.5 | AD25: 5 | AE25: Yes | AF25: Yes | AG25: 0 | AH25: 2227.93 | AI25: 7 | AJ25: 7 | AK25: 0 | AL25: 0 | AM25: 800.17 | AN25: 8 | AO25: 4 | AP25: 4 | AQ25: 0 | AR25: 1427.76 | AX25: 9001070300 | AY25: 16956.724 | AZ25: 202635.3 | BA25: 0 | BB25: 0 | BC25: 2 | BD25: 202635.3 | BF25: Yes | BG25: 3573653.6 | BH25: 1486846.8 | BI25: 449 | BJ25: 224884.29 | BK25: 898 | BL25: 1232002.5
A26: 1400000US09001070200 | B26: 9001070200 | C26: Census Tract 702, Fairfield County, Connecticut | D26: 42688 | E26: 2.37 | F26: 27728.836 | G26: 27.729 | H26: 0.139 | I26: 1 | J26: 0.861 | K26: 5 | L26: 1292 | M26: 0.55912914 | N26: 0.897 | O26: 5 | P26: 0.662 | Q26: 4 | R26: 5 | S26: 1 | T26: 1 | U26: 4052 | V26: 0.32567255 | W26: 12441.945 | X26: 1 | Y26: 665 | Z26: 17.139175 | AA26: 0.661 | AB26: 4 | AC26: 4.5 | AD26: 5 | AE26: Yes | AF26: Yes | AG26: 45704.852 | AH26: 0 | AI26: 0 | AM26: 0 | AN26: 0 | AR26: 0 | AX26: 9001070400 | AY26: 17917.036 | AZ26: 1029.53 | BA26: 3 | BB26: 380.24 | BC26: 6 | BD26: 649.29
